Workbook

Sheet Entreprises
A1: Ville | B1: Catégorie (secteur) | C1: Nom de l'entreprise | D1: Produits / services offerts | E1: Prix (si disponible) | F1: Lien de géolocalisation (Google Maps) | G1: Site web (recherche Google) | H1: Note Google /5 | I1: Nb d'avis | J1: Avis des clients (synthèse) | K1: Téléphone
A2: Douala | B2: Restauration | C2: The Yard | D2: Restaurant-lounge, cuisine variée, cocktails, DJ | E2: Niveau Google : $$$ (cocktails jugés chers) | F2: Voir sur Google Maps | G2: Chercher le site web | H2: 4.4 | I2: 133 | J2: Cadre chic, service pro et DJ appréciés ; cuisine bonne mais prix élevés. | K2: +237 671 49 07 33
A3: Douala | B3: Restauration | C3: One Rooftop | D3: Restaurant, lounge-bar et club en rooftop ; cuisines internationales, dim sum, sushi | E3: Niveau Google : $$$$ (~40 € minimum le dîner selon un avis) | F3: Voir sur Google Maps | G3: Chercher le site web | H3: 4.3 | I3: 765 | J3: Décor raffiné, cocktails et finger-food salués ; très cher. | K3: +237 671 03 33 33
A4: Douala | B4: Restauration | C4: Piccola Venezia Restaurant | D4: Restaurant italien : pizzas, pâtes | E4: Non communiqué | F4: Voir sur Google Maps | G4: Chercher le site web | H4: 4.3 | I4: 318 | J4: Pizzas et pâtes très appréciées, personnel attentionné ; manque une terrasse. | K4: +237 699 93 17 21
A5: Douala | B5: Restauration | C5: La Fourchette | D5: Restaurant, bar, espace lounge ; cuisine européenne | E5: Niveau Google : non indiqué (jugé cher, vins onéreux) | F5: Voir sur Google Maps | G5: Chercher le site web | H5: 4.1 | I5: 478 | J5: Personnel pro, ambiance jazz ; peu de choix végétarien, prix élevés, parking limité. | K5: +237 699 92 64 66
A6: Douala | B6: Restauration | C6: VAULT CMR | D6: Restaurant lounge sur toit avec musique live, cocktails | E6: Non communiqué | F6: Voir sur Google Maps | G6: Chercher le site web | H6: 4.6 | I6: 68 | J6: Ambiance chic et calme, cocktails et plats bien notés. | K6: +237 675 12 48 70
A7: Douala | B7: Restauration | C7: Le Grilladin Restaurant | D7: Buffet à volonté de cuisine camerounaise, bar, karaoké | E7: Buffet dîner : 10 000 FCFA/personne (avis client) | F7: Voir sur Google Maps | G7: Chercher le site web | H7: 4 | I7: 823 | J7: Ambiance agréable et bon rapport prix ; qualité de la cuisine variable. | K7: +237 694 53 63 71
A8: Douala | B8: Restauration | C8: Maison H | D8: Café-restaurant, glacier, pâtes et desserts | E8: Niveau Google : non indiqué (jugé un peu cher) | F8: Voir sur Google Maps | G8: Chercher le site web | H8: 4.3 | I8: 3115 | J8: Cadre calme et élégant, pâtes et glaces très appréciées ; assez cher. | K8: +237 656 00 55 55
A9: Douala | B9: Restauration | C9: L'Ethnic Restaurant | D9: Cuisine africaine (Cameroun, Sénégal, Côte d'Ivoire), cocktails | E9: Niveau Google : $$$$ | F9: Voir sur Google Maps | G9: Chercher le site web | H9: 4.3 | I9: 177 | J9: Nourriture excellente, cadre soigné, restaurant tenu par une Camerounaise ; dress code. | K9: +237 671 25 91 54
A10: Douala | B10: Hôtellerie | C10: ONOMO Hotel Douala | D10: Hôtel, restaurant, bar, navette aéroport | E10: Chambre standard : ~135 €/nuit (un avis client) | F10: Voir sur Google Maps | G10: Chercher le site web | H10: 4.2 | I10: 1377 | J10: Service et restaurant salués ; quelques critiques sur l'entretien des chambres. | K10: +237 695 00 00 00
A11: Douala | B11: Hôtellerie | C11: Saffana Hotel | D11: Hôtel proche de l'aéroport, restaurant, navette | E11: Non communiqué | F11: Voir sur Google Maps | G11: Chercher le site web | H11: 3.5 | I11: 1005 | J11: Personnel accueillant, bien situé ; Wi-Fi et TV à améliorer. | K11: +237 659 31 00 34
A12: Douala | B12: Hôtellerie | C12: Hotel Akwa Palace Douala | D12: Hôtel historique, restaurant, bar, salles d'événements, piscine | E12: Non communiqué | F12: Voir sur Google Maps | G12: Chercher le site web | H12: 4.1 | I12: 3330 | J12: Accueil et service appréciés ; bâtiment et literie à moderniser. | K12: +237 233 42 26 01
A13: Douala | B13: Hôtellerie | C13: K Hotel Douala | D13: Hôtel, restaurant, bar-piscine, événements | E13: Non communiqué | F13: Voir sur Google Maps | G13: Chercher le site web | H13: 4.5 | I13: 928 | J13: Très bien noté (déco, service, ménage 2x/jour) ; quelques avis négatifs sur le management. | K13: +237 233 50 74 00
... A17: Douala | B17: Hôtellerie | C17: Hôtel JOANA | D17: Hôtel économique | E17: Chambres abordables (avis) | F17: Voir sur Google Maps | G17: Chercher le site web | H17: 3.5 | I17: 228 | J17: Propre, calme et bon marché ; quelques travaux restent à finir. | K17: +237 653 55 63 55
A18: Douala | B18: Banque & Finance | C18: Afriland First Bank Mboppi | D18: Banque : comptes, cartes, guichet | E18: Non communiqué | F18: Voir sur Google Maps | G18: Chercher le site web | H18: 4.1 | I18: 34 | J18: Agence facile à repérer, avis courts et positifs.
A19: Douala | B19: Banque & Finance | C19: Union Bank of Cameroon | D19: Banque : services bancaires courants | E19: Non communiqué | F19: Voir sur Google Maps | G19: Chercher le site web | H19: 4.4 | I19: 14 | J19: Service fluide et correct. | K19: +237 233 42 25 08
A20: Douala | B20: Banque & Finance | C20: AFG Bank Cameroun (Siège social) | D20: Banque : comptes, cartes, DAB | E20: Non communiqué | F20: Voir sur Google Maps | G20: Chercher le site web | H20: 3.6 | I20: 38 | J20: Personnel bilingue et gamme de comptes ; avis partagés sur la lenteur. | K20: +237 233 50 99 00
A21: Douala | B21: Banque & Finance | C21: Atlantic Bank Ndogbong | D21: Banque : services bancaires courants | E21: Non communiqué | F21: Voir sur Google Maps | G21: Chercher le site web | H21: 3.1 | I21: 37 | J21: Accueil jugé médiocre par plusieurs clients. | K21: +237 691 92 75 55
A22: Douala | B22: Banque & Finance | C22: UBA Cameroon Head Office | D22: Banque : siège, comptes, transferts, cartes | E22: Non communiqué | F22: Voir sur Google Maps | G22: Chercher le site web | H22: 3.9 | I22: 100 | J22: Équipe réactive mais files d'attente longues. | K22: +237 233 50 67 82
A23: Douala | B23: Banque & Finance | C23: SCB Cameroun (Attijariwafa Bank) | D23: Banque : comptes, DAB (réseau Total) | E23: Non communiqué | F23: Voir sur Google Maps | G23: Chercher le site web | H23: 3.2 | I23: 35 | J23: Réseau de DAB apprécié ; service client critiqué. | K23: +237 233 43 53 00
A24: Douala | B24: Banque & Finance | C24: SGC Bank Bonanjo | D24: Banque : services bancaires courants | E24: Non communiqué | F24: Voir sur Google Maps | G24: Chercher le site web | H24: 4 | I24: 57 | J24: Bons locaux, service perfectible. | K24: +237 233 50 18 18
A25: Douala | B25: Banque & Finance | C25: Banque Atlantique Joss | D25: Banque : services bancaires courants | E25: Non communiqué | F25: Voir sur Google Maps | G25: Chercher le site web | H25: 3.7 | I25: 9 | J25: Service rapide pour certains ; bâtiment vieillissant. | K25: +237 233 42 10 66
A26: Douala | B26: Pharmacie | C26: Pharmacie de Douala | D26: Pharmacie ouverte 24h/24 | E26: Non communiqué | F26: Voir sur Google Maps | G26: Chercher le site web | H26: 4.8 | I26: 6 | J26: Peu d'avis, note élevée. | K26: +237 698 00 26 69
A27: Douala | B27: Pharmacie | C27: Pharmacy Kotto | D27: Pharmacie, large gamme de produits médicaux | E27: Non communiqué | F27: Voir sur Google Maps | G27: Chercher le site web | H27: 4 | I27: 68 | J27: Grande pharmacie bien fournie ; un client la dit fermée un jour. | K27: +237 697 04 10 56
A28: Douala | B28: Pharmacie | C28: Pharmacie de Logpom | D28: Pharmacie de garde 24h/24 | E28: Non communiqué | F28: Voir sur Google Maps | G28: Chercher le site web | H28: 3.7 | I28: 39 | J28: Personnel accueillant et compétent, utile la nuit. | K28: +237 233 77 39 13
A29: Douala | B29: Pharmacie | C29: Pharmacie de l'Alliance | D29: Pharmacie, médicaments | E29: Non communiqué | F29: Voir sur Google Maps | G29: Chercher le site web | H29: 4.1 | I29: 54 | J29: Personnel compétent, bons conseils. | K29: +237 233 42 99 15
A30: Douala | B30: Pharmacie | C30: Pharmacie du Plateau | D30: Pharmacie 24h/24 à Bonapriso | E30: Non communiqué | F30: Voir sur Google Maps | G30: Chercher le site web | H30: 4.2 | I30: 33 | J30: Bien organisée, service rapide et aimable. | K30: +237 679 70 46 26
... A111: Douala | B111: BTP & matériaux de construction | C111: TC BTP SARL | D111: Entreprise de BTP et finitions | E111: Non communiqué | F111: Voir sur Google Maps | G111: Chercher le site web | H111: 5 | I111: 5 | J111: Respect des délais, finitions de qualité. | K111: +237 699 63 38 82
A112: Douala | B112: BTP & matériaux de construction | C112: Royal Construction Cameroun | D112: Tôles bac, tuiles ondulées, fournitures de construction | E112: Non communiqué | F112: Voir sur Google Maps | G112: Chercher le site web | H112: 4.5 | I112: 2 | J112: Produits et service de très bonne qualité.
A113: Douala | B113: BTP & matériaux de construction | C113: COGENI Bonamoussadi | D113: Quincaillerie et matériaux en gros | E113: Prix compétitifs (avis) | F113: Voir sur Google Maps | G113: Chercher le site web | H113: 3.7 | I113: 63 | J113: Prix intéressants ; un avis critique sur l'accueil. | K113: +237 671 34 04 31
A114: Douala | B114: Juridique (avocats / notaires) | C114: Cabinet d'Avocats Nguéé & Associés | D114: Cabinet d'avocats | E114: Non communiqué | F114: Voir sur Google Maps | G114: Chercher le site web | H114: 4.7 | I114: 36 | J114: Équipe jeune, dynamique et à l'écoute. | K114: +237 242 00 96 12
A115: Douala | B115: Juridique (avocats / notaires) | C115: Bitanga & Partners Law Firm | D115: Cabinet d'avocats : droit des affaires, fiscal | E115: Non communiqué | F115: Voir sur Google Maps | G115: Chercher le site web | H115: 4.7 | I115: 56 | J115: Approche moderne et transparente ; certains dossiers longs. | K115: +237 620 11 98 77
A116: Douala | B116: Juridique (avocats / notaires) | C116: 4M Legal and Tax | D116: Conseil juridique et fiscal, création d'entreprise | E116: Non communiqué | F116: Voir sur Google Maps | G116: Chercher le site web | H116: 4.9 | I116: 54 | J116: Très bien noté : professionnalisme et suivi étape par étape. | K116: +237 698 10 53 19
A117: Douala | B117: Juridique (avocats / notaires) | C117: Cabinet Notaire (Me Eboutou) | D117: Étude notariale | E117: Non communiqué | F117: Voir sur Google Maps | G117: Chercher le site web | H117: 3.5 | I117: 2 | J117: Peu d'avis. | K117: +237 233 43 16 62
A118: Douala | B118: Juridique (avocats / notaires) | C118: Maaron Law Firm | D118: Cabinet juridique | E118: Non communiqué | F118: Voir sur Google Maps | G118: Chercher le site web | H118: 5 | I118: 1 | J118: Un seul avis. | K118: +237 680 35 12 25
A119: Douala | B119: Communication & impression | C119: Group M.A.O – Agence de communication | D119: Gestion de pages/réseaux sociaux, monétisation | E119: Non communiqué | F119: Voir sur Google Maps | G119: Chercher le site web | H119: 5 | I119: 8 | J119: Clients satisfaits de la gestion de leurs comptes. | K119: +237 675 18 74 31
A120: Douala | B120: Communication & impression | C120: Easyprinting Cameroon | D120: Impression, objets publicitaires, diplômes et attestations | E120: Non communiqué | F120: Voir sur Google Maps | G120: Chercher le site web | H120: 4.3 | I120: 12 | J120: Impression de qualité, clients satisfaits. | K120: +237 697 80 86 50
A121: Douala | B121: Communication & impression | C121: Jerry Kamgang | D121: Formations en marketing digital (Facebook, WhatsApp) | E121: Non communiqué | F121: Voir sur Google Maps | G121: Chercher le site web | H121: 4.8 | I121: 281 | J121: Formation bien structurée et très appréciée ; un avis déçu. | K121: +237 696 34 30 36
A122: Douala | B122: Communication & impression | C122: AJC Graphic SARL | D122: Imprimerie, conception graphique | E122: Non communiqué | F122: Voir sur Google Maps | G122: Chercher le site web | H122: 4 | I122: 1 | J122: Un seul avis. | K122: +237 699 91 25 89
A123: Douala | B123: Communication & impression | C123: Digital Print Cameroun | D123: Impression numérique | E123: Non communiqué | F123: Voir sur Google Maps | G123: Chercher le site web | H123: 4.7 | I123: 6 | J123: Équipe jeune, dynamique et professionnelle. | K123: +237 658 90 00 00
...

Sheet Synthèse
A1: Nombre d'entreprises par ville et catégorie
A3: Catégorie | B3: Douala | C3: Yaoundé | D3: Bafoussam | E3: Total
A4: Restauration | B4: =COUNTIFS(Entreprises!$A$2:$A$315,B$3,Entreprises!$B$2:$B$315,$A4) -> 8 | C4: =COUNTIFS(Entreprises!$A$2:$A$315,C$3,Entreprises!$B$2:$B$315,$A4) -> 5 | D4: =COUNTIFS(Entreprises!$A$2:$A$315,D$3,Entreprises!$B$2:$B$315,$A4) -> 5 | E4: =SUM(B4:D4) -> 18
A5: Hôtellerie | B5: =COUNTIFS(Entreprises!$A$2:$A$315,B$3,Entreprises!$B$2:$B$315,$A5) -> 8 | C5: =COUNTIFS(Entreprises!$A$2:$A$315,C$3,Entreprises!$B$2:$B$315,$A5) -> 5 | D5: =COUNTIFS(Entreprises!$A$2:$A$315,D$3,Entreprises!$B$2:$B$315,$A5) -> 5 | E5: =SUM(B5:D5) -> 18
A6: Banque & Finance | B6: =COUNTIFS(Entreprises!$A$2:$A$315,B$3,Entreprises!$B$2:$B$315,$A6) -> 8 | C6: =COUNTIFS(Entreprises!$A$2:$A$315,C$3,Entreprises!$B$2:$B$315,$A6) -> 5 | D6: =COUNTIFS(Entreprises!$A$2:$A$315,D$3,Entreprises!$B$2:$B$315,$A6) -> 5 | E6: =SUM(B6:D6) -> 18
A7: Pharmacie | B7: =COUNTIFS(Entreprises!$A$2:$A$315,B$3,Entreprises!$B$2:$B$315,$A7) -> 8 | C7: =COUNTIFS(Entreprises!$A$2:$A$315,C$3,Entreprises!$B$2:$B$315,$A7) -> 5 | D7: =COUNTIFS(Entreprises!$A$2:$A$315,D$3,Entreprises!$B$2:$B$315,$A7) -> 5 | E7: =SUM(B7:D7) -> 18
A8: Commerce & Grande distribution | B8: =COUNTIFS(Entreprises!$A$2:$A$315,B$3,Entreprises!$B$2:$B$315,$A8) -> 8 | C8: =COUNTIFS(Entreprises!$A$2:$A$315,C$3,Entreprises!$B$2:$B$315,$A8) -> 5 | D8: =COUNTIFS(Entreprises!$A$2:$A$315,D$3,Entreprises!$B$2:$B$315,$A8) -> 5 | E8: =SUM(B8:D8) -> 18
A9: Santé (cliniques / hôpitaux) | B9: =COUNTIFS(Entreprises!$A$2:$A$315,B$3,Entreprises!$B$2:$B$315,$A9) -> 8 | C9: =COUNTIFS(Entreprises!$A$2:$A$315,C$3,Entreprises!$B$2:$B$315,$A9) -> 5 | D9: =COUNTIFS(Entreprises!$A$2:$A$315,D$3,Entreprises!$B$2:$B$315,$A9) -> 5 | E9: =SUM(B9:D9) -> 18
A10: Éducation & Formation | B10: =COUNTIFS(Entreprises!$A$2:$A$315,B$3,Entreprises!$B$2:$B$315,$A10) -> 8 | C10: =COUNTIFS(Entreprises!$A$2:$A$315,C$3,Entreprises!$B$2:$B$315,$A10) -> 5 | D10: =COUNTIFS(Entreprises!$A$2:$A$315,D$3,Entreprises!$B$2:$B$315,$A10) -> 5 | E10: =SUM(B10:D10) -> 18
A11: Automobile (garages) | B11: =COUNTIFS(Entreprises!$A$2:$A$315,B$3,Entreprises!$B$2:$B$315,$A11) -> 8 | C11: =COUNTIFS(Entreprises!$A$2:$A$315,C$3,Entreprises!$B$2:$B$315,$A11) -> 5 | D11: =COUNTIFS(Entreprises!$A$2:$A$315,D$3,Entreprises!$B$2:$B$315,$A11) -> 5 | E11: =SUM(B11:D11) -> 18
A12: Voyage & Transport | B12: =COUNTIFS(Entreprises!$A$2:$A$315,B$3,Entreprises!$B$2:$B$315,$A12) -> 8 | C12: =COUNTIFS(Entreprises!$A$2:$A$315,C$3,Entreprises!$B$2:$B$315,$A12) -> 5 | D12: =COUNTIFS(Entreprises!$A$2:$A$315,D$3,Entreprises!$B$2:$B$315,$A12) -> 5 | E12: =SUM(B12:D12) -> 18
A13: Beauté & Bien-être | B13: =COUNTIFS(Entreprises!$A$2:$A$315,B$3,Entreprises!$B$2:$B$315,$A13) -> 8 | C13: =COUNTIFS(Entreprises!$A$2:$A$315,C$3,Entreprises!$B$2:$B$315,$A13) -> 5 | D13: =COUNTIFS(Entreprises!$A$2:$A$315,D$3,Entreprises!$B$2:$B$315,$A13) -> 5 | E13: =SUM(B13:D13) -> 18
A14: Assurance | B14: =COUNTIFS(Entreprises!$A$2:$A$315,B$3,Entreprises!$B$2:$B$315,$A14) -> 5 | C14: =COUNTIFS(Entreprises!$A$2:$A$315,C$3,Entreprises!$B$2:$B$315,$A14) -> 4 | D14: =COUNTIFS(Entreprises!$A$2:$A$315,D$3,Entreprises!$B$2:$B$315,$A14) -> 5 | E14: =SUM(B14:D14) -> 14
A15: Immobilier | B15: =COUNTIFS(Entreprises!$A$2:$A$315,B$3,Entreprises!$B$2:$B$315,$A15) -> 5 | C15: =COUNTIFS(Entreprises!$A$2:$A$315,C$3,Entreprises!$B$2:$B$315,$A15) -> 5 | D15: =COUNTIFS(Entreprises!$A$2:$A$315,D$3,Entreprises!$B$2:$B$315,$A15) -> 3 | E15: =SUM(B15:D15) -> 13
... A23: Sport & loisirs | B23: =COUNTIFS(Entreprises!$A$2:$A$315,B$3,Entreprises!$B$2:$B$315,$A23) -> 5 | C23: =COUNTIFS(Entreprises!$A$2:$A$315,C$3,Entreprises!$B$2:$B$315,$A23) -> 5 | D23: =COUNTIFS(Entreprises!$A$2:$A$315,D$3,Entreprises!$B$2:$B$315,$A23) -> 4 | E23: =SUM(B23:D23) -> 14
A24: Total | B24: =SUM(B4:B23) -> 127 | C24: =SUM(C4:C23) -> 99 | D24: =SUM(D4:D23) -> 88 | E24: =SUM(E4:E23) -> 314
A26: Notes & méthode
A27: • Source : Google Maps / Google Places (recherche par catégorie et par ville) ; données collectées le 21/09/2026.
A28: • Ce fichier est un ÉCHANTILLON représentatif (20 secteurs × 3 villes), pas une liste exhaustive : des dizaines de milliers d'entreprises sont référencées sur Google Maps dans ces villes.
A29: • Prix : Google Maps n'affiche pas les tarifs. Les montants indiqués proviennent d'avis clients (à vérifier) ; sinon le niveau de prix Google ($ à $$$$) est repris quand il existe.
A30: • Avis : note et nombre d'avis proviennent de Google ; la synthèse est une reformulation des avis récents affichés (pas une citation).
A31: • Lien : ouvre la fiche de l'établissement sur Google Maps (coordonnées GPS + identifiant du lieu). Le bouton « Site web » de la fiche Maps, quand il existe, mène au site officiel.
A32: • Site web : la colonne contient un lien de recherche Google (nom + ville) vers le site officiel ; les URL n'ont pas pu être extraites automatiquement de façon fiable. Beaucoup de PME locales n'ont qu'une page Facebook/WhatsApp, sans site.
A33: • Certaines fiches ont peu ou pas d'avis, ou des horaires/numéros à confirmer : vérifiez avant de vous déplacer.
